Workbook

Sheet 模型总览与设计逻辑
A1: 钢铁行业减碳基准路径模型 V7 - 行业基准校准版
A2: 由碳强度目标倒推技术路径比例 | 基准年碳强度=1.95 | 2024-2060逐年 | CCUS百万吨起步
A4: 一、模型目的
A5: 本模型为金融机构转型金融业务提供钢铁行业减碳基准路径参考。
A6: 核心方法论: 自上而下(CG碳预算) + 自下而上(行业技术路径) 双路径耦合。
A7: 模型本质: 由结果(碳强度目标)倒推过程(技术路径比例)，确保关键年份目标对齐。
A9: 二、全局硬性规定
A10: 1. 禁止硬编码: 除Step1/2基准数据外，所有数值由公式生成。
A11: 2. 年份连续: 2024-2060每一年数据，不得省略。
A12: 3. 情景梯度: 保守 > 适度 > 积极(每年都必须成立)。
A13: 4. 基准年约束: 2024年碳强度=1.95, 2025年碳强度=1.904(三情景统一, 自然效应)。
A14: 5. 单位规范: 产量(万吨), 碳排放(万吨CO2), 碳强度(tCO2/t)。
... A17: 三、关键年份目标(已校准)
A18: 指标 | B18: 积极 | C18: 适度 | D18: 保守
A19: 2024碳强度 | B19: 1.9500 | C19: 1.9500 | D19: 1.9500
A20: 2025碳强度 | B20: 1.9051 | C20: 1.9051 | D20: 1.9051
A21: 2030碳强度 | B21: 1.5920 | C21: 1.7990 | D21: 1.8425
A22: 2030降幅(vs2024) | B22: -18.36% | C22: -7.74% | D22: -5.52%
A23: 2035碳强度 | B23: 1.1734 | C23: 1.6185 | D23: 1.6814
A24: 2060碳强度 | B24: 0.0040 | C24: 0.0060 | D24: 0.0080
A25: 2060 CCUS(亿吨) | B25: 2.7 | C25: 4.1 | D25: 5.6
A27: 四、基准年参数(Step 2)
A28: 基准年 | B28: 2024 | C28: 长流程废钢比(%) | D28: 30
A29: 粗钢产量(万吨) | B29: 100,509 | C29: 短流程废钢比(%) | D29: 100
A30: 碳排放总量(万吨CO2) | B30: 195,992 | C30: 氢冶金废钢比(%) | D30: 50
A31: 吨钢碳排放强度(tCO2/t) | B31: 1.95 | C31: 吨钢耗废钢量 | D31: 1.1
A32: 长流程产量占比(%) | B32: 89 | C32: 吨钢耗铁水量 | D32: 1.053
A33: 短流程产量占比(%) | B33: 10 | C33: 吨铁水耗铁矿石量 | D33: 1.65
A34: 氢冶金产量占比(%) | B34: 1 | C34: BF-BOF碳排放强度(tCO2/t) | D34: 1.80
C35: Scrap-EAF碳排放强度(tCO2/t) | D35: 0.45
C36: 长流程铁水碳排放强度(tCO2/t) | D36: 1.26
C37: DRI-EAF碳排放强度(tCO2/t) | D37: 1.65
C38: 电网因子(kgCO2/kWh) | D38: 0.5306
C39: BF-BOF耗电(kWh/t) | D39: 450
C40: Scrap-EAF耗电(kWh/t) | D40: 550
C41: DRI-EAF耗电(kWh/t) | D41: 500
A43: 五、Sheet索引
A44: Sheet 1 | B44: 模型总览与设计逻辑 | C44: 本页
A45: Sheet 2 | B45: 积极情景 | C45: NZE/1.5C路线图
A46: Sheet 3 | B46: 适度情景 | C46: CGE 2C(推荐对标)
...

Sheet 积极情景
A1: 钢铁行业减碳基准路径 - 积极情景
A2: 基准年2024 | 碳强度1.95 tCO2/t | CCUS百万吨起步 | 2024-2060逐年
A4: 指标 | B4: 公式说明 | C4: 2024 | D4: 2025 | E4: 2026 | F4: 2027 | G4: 2028 | H4: 2029 | I4: 2030 | J4: 2031 | K4: 2032 | L4: 2033 | M4: 2034 | N4: 2035 | O4: 2036 | P4: 2037 | Q4: 2038 | R4: 2039 | S4: 2040 | T4: 2041 | U4: 2042 | V4: 2043 | W4: 2044 | X4: 2045 | Y4: 2046 | Z4: 2047 | AA4: 2048 | AB4: 2049 | AC4: 2050 | AD4: 2051 | AE4: 2052 | AF4: 2053 | AG4: 2054 | AH4: 2055 | AI4: 2056 | AJ4: 2057 | AK4: 2058 | AL4: 2059 | AM4: 2060 | AP4: Step 2: 基准年参数
A5: Step 1: 宏观经济假设 | AP5: 参数名称 | AQ5: 参数值
A6: GDP增长率(%) | B6: 国家统计局/IFS-CGE | C6: 4.9 | D6: 4.5 | E6: 4.3 | F6: 4.1 | G6: 3.9 | H6: 3.7 | I6: 3.5 | J6: 3.3 | K6: 3.1 | L6: 3 | M6: 2.8 | N6: 2.7 | O6: 2.5 | P6: 2.4 | Q6: 2.2 | R6: 2.1 | S6: 2 | T6: 1.8 | U6: 1.7 | V6: 1.6 | W6: 1.5 | X6: 1.5 | Y6: 1.3 | Z6: 1.2 | AA6: 1.1 | AB6: 1 | AC6: 1 | AD6: 0.8 | AE6: 0.7 | AF6: 0.6 | AG6: 0.6 | AH6: 0.5 | AI6: 0.4 | AJ6: 0.4 | AK6: 0.3 | AL6: 0.3 | AM6: 0.2 | AP6: 基准年 | AQ6: 2024
A7: 实际GDP(2020价万亿) | B7: 支出法GDP | C7: 124.92 | D7: 130.54 | E7: 135.62767 | F7: 140.91362 | G7: 146.40559 | H7: 152.1116 | I7: 158.04 | J7: 162.7489 | K7: 167.59811 | L7: 172.59181 | M7: 177.73429 | N7: 183.03 | O7: 187.13014 | P7: 191.32213 | Q7: 195.60803 | R7: 199.98993 | S7: 204.47 | T7: 207.27266 | U7: 210.11373 | V7: 212.99374 | W7: 215.91323 | X7: 218.87274 | Y7: 221.87281 | Z7: 224.91401 | AA7: 227.99689 | AB7: 231.12203 | AC7: 234.29 | AD7: 235.41536 | AE7: 236.54613 | AF7: 237.68233 | AG7: 238.82398 | AH7: 239.97112 | AI7: 241.12377 | AJ7: 242.28196 | AK7: 243.44571 | AL7: 244.61504 | AM7: 245.79 | AP7: 粗钢产量(万吨) | AQ7: 100,509
A8: 人口(亿人) | B8: 联合国中位预测 | C8: 14.08 | D8: 14.08 | E8: 14.053903 | F8: 14.027855 | G8: 14.001855 | H8: 13.975904 | I8: 13.95 | J8: 13.909769 | K8: 13.869653 | L8: 13.829654 | M8: 13.789769 | N8: 13.75 | O8: 13.699632 | P8: 13.649449 | Q8: 13.59945 | R8: 13.549634 | S8: 13.5 | T8: 13.434592 | U8: 13.369501 | V8: 13.304726 | W8: 13.240264 | X8: 13.176115 | Y8: 13.112276 | Z8: 13.048747 | AA8: 12.985525 | AB8: 12.92261 | AC8: 12.86 | AD8: 12.782956 | AE8: 12.706373 | AF8: 12.630249 | AG8: 12.554581 | AH8: 12.479367 | AI8: 12.404603 | AJ8: 12.330287 | AK8: 12.256416 | AL8: 12.182988 | AM8: 12.11 | AP8: 碳排放总量(万吨CO2) | AQ8: 195,992
A9: 全国CO2排放(亿吨) | B9: IFS-CGE模型 | C9: 106.5 | D9: 108 | E9: 110 | F9: 112 | G9: 115 | H9: 117 | I9: 118 | J9: 117 | K9: 115.5 | L9: 113.5 | M9: 111 | N9: 109 | O9: 106.5 | P9: 103.5 | Q9: 100 | R9: 96 | S9: 92 | T9: 87.5 | U9: 83 | V9: 78.5 | W9: 74 | X9: 69.5 | Y9: 65 | Z9: 60.5 | AA9: 56 | AB9: 51.5 | AC9: 47 | AD9: 43 | AE9: 39 | AF9: 35.5 | AG9: 32 | AH9: 29 | AI9: 26.5 | AJ9: 24.5 | AK9: 23 | AL9: 22 | AM9: 21 | AP9: 吨钢碳排放强度(tCO2/t) | AQ9: 1.95
A10: 吨钢综合能耗(kgce/t) | B10: 2025+1.9%: 产品结构调整+超低排放+入炉矿品位下降 | C10: 1.85 | D10: 1.88515 | E10: 1.8757242 | F10: 1.8607185 | G10: 1.8421113 | H10: 1.8200059 | I10: 1.7927058 | J10: 1.7658153 | K10: 1.739328 | L10: 1.7132381 | M10: 1.6875395 | N10: 1.6622264 | O10: 1.6422797 | P10: 1.6225724 | Q10: 1.6031015 | R10: 1.5838643 | S10: 1.5680256 | T10: 1.5523454 | U10: 1.5368219 | V10: 1.5214537 | W10: 1.5092821 | X10: 1.4972078 | Y10: 1.4852302 | Z10: 1.4733483 | AA10: 1.4645082 | AB10: 1.4557212 | AC10: 1.4469869 | AD10: 1.4397519 | AE10: 1.4325532 | AF10: 1.4253904 | AG10: 1.4182634 | AH10: 1.4125904 | AI10: 1.40694 | AJ10: 1.4013123 | AK10: 1.3971083 | AL10: 1.392917 | AM10: 1.3887383
A11: 吨钢综合能耗同比变化(%) | B11: 国家统计局/中钢协数据 | C11: 0 | D11: 1.9 | E11: -0.5 | F11: -0.8 | G11: -1 | H11: -1.2 | I11: -1.5 | J11: -1.5 | K11: -1.5 | L11: -1.5 | M11: -1.5 | N11: -1.5 | O11: -1.2 | P11: -1.2 | Q11: -1.2 | R11: -1.2 | S11: -1 | T11: -1 | U11: -1 | V11: -1 | W11: -0.8 | X11: -0.8 | Y11: -0.8 | Z11: -0.8 | AA11: -0.6 | AB11: -0.6 | AC11: -0.6 | AD11: -0.5 | AE11: -0.5 | AF11: -0.5 | AG11: -0.5 | AH11: -0.4 | AI11: -0.4 | AJ11: -0.4 | AK11: -0.3 | AL11: -0.3 | AM11: -0.3 | AP11: ---工艺参数---
A12: Step 3: 粗钢产量(万吨) | AP12: 长流程产量占比(%) | AQ12: 89
A13: 粗钢产量(万吨) | B13: CAGR插值(三情景共用) | C13: 100509 | D13: 96081 | E13: 93000 | F13: 91000 | G13: 89000 | H13: 87000 | I13: 85000 | J13: 83500 | K13: 82000 | L13: 80800 | M13: 79600 | N13: 78500 | O13: 77500 | P13: 76500 | Q13: 75500 | R13: 74500 | S13: 73600 | T13: 72800 | U13: 72000 | V13: 71300 | W13: 70600 | X13: 69900 | Y13: 69300 | Z13: 68700 | AA13: 68200 | AB13: 67700 | AC13: 67200 | AD13: 66600 | AE13: 66000 | AF13: 65400 | AG13: 64800 | AH13: 64200 | AI13: 63600 | AJ13: 63000 | AK13: 62500 | AL13: 62000 | AM13: 61600 | AP13: 短流程产量占比(%) | AQ13: 10
A14: Step 4: 流程结构 | AP14: 氢冶金产量占比(%) | AQ14: 1
A15: 短流程产量占比(%) | B15: 二分法校准 | C15: 10 | D15: 10.666667 | E15: 11.333333 | F15: 12 | G15: 12.666667 | H15: 13.333333 | I15: 14 | J15: 15.2 | K15: 16.4 | L15: 17.6 | M15: 18.8 | N15: 20 | O15: 21.6 | P15: 23.2 | Q15: 24.8 | R15: 26.4 | S15: 28 | T15: 29 | U15: 30 | V15: 31 | W15: 32 | X15: 33 | Y15: 34 | Z15: 35 | AA15: 36 | AB15: 37 | AC15: 38 | AD15: 39 | AE15: 40 | AF15: 41 | AG15: 42 | AH15: 43 | AI15: 44 | AJ15: 45 | AK15: 46 | AL15: 47 | AM15: 48
A16: 氢冶金产量占比(%) | B16: 情景差异化 | C16: 1 | D16: 1.1666667 | E16: 1.3333333 | F16: 1.5 | G16: 1.6666667 | H16: 1.8333333 | I16: 2 | J16: 2.4 | K16: 2.8 | L16: 3.2 | M16: 3.6 | N16: 4 | O16: 4.8 | P16: 5.6 | Q16: 6.4 | R16: 7.2 | S16: 8 | T16: 8.6 | U16: 9.2 | V16: 9.8 | W16: 10.4 | X16: 11 | Y16: 11.6 | Z16: 12.2 | AA16: 12.8 | AB16: 13.4 | AC16: 14 | AD16: 14.4 | AE16: 14.8 | AF16: 15.2 | AG16: 15.6 | AH16: 16 | AI16: 16.4 | AJ16: 16.8 | AK16: 17.2 | AL16: 17.6 | AM16: 18 | AP16: 吨钢耗废钢量 | AQ16: 1.1
A17: 长流程产量占比(%) | B17: =1-短流程%-氢冶金% -> #NAME? | C17: =1-C15/100-C16/100 -> 0.89 | D17: =1-D15/100-D16/100 -> 0.88166667 | E17: =1-E15/100-E16/100 -> 0.87333333 | F17: =1-F15/100-F16/100 -> 0.865 | G17: =1-G15/100-G16/100 -> 0.85666667 | H17: =1-H15/100-H16/100 -> 0.84833333 | I17: =1-I15/100-I16/100 -> 0.84 | J17: =1-J15/100-J16/100 -> 0.824 | ... AM17: =1-AM15/100-AM16/100 -> 0.34 | AP17: 吨钢耗铁水量 | AQ17: 1.053
A18: 长流程产量(万吨) | B18: =长流程产量公式 -> #NAME? | C18: =C13*C17 -> 89453.01 | D18: =D13*D17 -> 84711.415 | E18: =E13*E17 -> 81220 | F18: =F13*F17 -> 78715 | G18: =G13*G17 -> 76243.333 | H18: =H13*H17 -> 73805 | I18: =I13*I17 -> 71400 | J18: =J13*J17 -> 68804 | ... AM18: =AM13*AM17 -> 20944 | AP18: 吨铁水耗铁矿石量 | AQ18: 1.65
A19: 短流程产量(万吨) | B19: =短流程产量公式 -> #NAME? | C19: =C13*C15/100 -> 10050.9 | D19: =D13*D15/100 -> 10248.64 | E19: =E13*E15/100 -> 10540 | F19: =F13*F15/100 -> 10920 | G19: =G13*G15/100 -> 11273.333 | H19: =H13*H15/100 -> 11600 | I19: =I13*I15/100 -> 11900 | J19: =J13*J15/100 -> 12692 | ... AM19: =AM13*AM15/100 -> 29568
A20: 氢冶金产量(万吨) | B20: =氢冶金产量公式 -> #NAME? | C20: =C13*C16/100 -> 1005.09 | D20: =D13*D16/100 -> 1120.945 | E20: =E13*E16/100 -> 1240 | F20: =F13*F16/100 -> 1365 | G20: =G13*G16/100 -> 1483.3333 | H20: =H13*H16/100 -> 1595 | I20: =I13*I16/100 -> 1700 | J20: =J13*J16/100 -> 2004 | ... AM20: =AM13*AM16/100 -> 11088 | AP20: BF-BOF碳排放强度 | AQ20: 1.80 tCO2/t
A21: Step 5: 铁素资源结构 | AP21: Scrap-EAF碳排放强度 | AQ21: 0.45 tCO2/t
A22: 废钢资源量参考(万吨/年) | B22: 崔志峰等(2023): 2045峰值约5亿吨, 2050年4.7-5.2亿吨 | C22: 28820 | D22: 28219 | E22: 29961 | F22: 29382 | G22: 29386 | H22: 28778 | I22: 32732 | J22: 34435 | K22: 36658 | L22: 37830 | M22: 40503 | N22: 41237 | O22: 39624 | P22: 40341 | Q22: 43408 | R22: 48723 | S22: 49139 | T22: 53056 | U22: 53442 | V22: 57694 | W22: 56770 | X22: 57761 | Y22: 58218 | Z22: 58413 | AA22: 58398 | AB22: 58423 | AC22: 58294 | AD22: 57964 | AE22: 57618 | AF22: 58042 | AG22: 57652 | AH22: 58167 | AI22: 56985 | AJ22: 55820 | AK22: 54753 | AL22: 53677 | AM22: 52611 | AP22: DRI-EAF碳排放强度 | AQ22: 1.65 tCO2/t
A23: 长流程废钢消耗量(万吨) | B23: 铁素资源公式 | C23: =C18*0.3 -> 26835.903 | D23: =D18*0.3 -> 25413.424 | E23: =E18*0.3 -> 24366 | F23: =F18*0.3 -> 23614.5 | G23: =G18*0.3 -> 22873 | H23: =H18*0.3 -> 22141.5 | I23: =I18*0.3 -> 21420 | J23: =J18*0.3 -> 20641.2 | ... AM23: =AM18*0.3 -> 6283.2 | AP23: 铁水碳排放强度 | AQ23: 1.26 tCO2/t
A24: 长流程矿石消耗量(万吨) | B24: 铁素资源公式 | C24: =(C18-C23/1.1)*1.053*1.65 -> 113032.82 | D24: =(D18-D23/1.1)*1.053*1.65 -> 107041.34 | E24: =(E18-E23/1.1)*1.053*1.65 -> 102629.59 | F24: =(F18-F23/1.1)*1.053*1.65 -> 99464.274 | G24: =(G18-G23/1.1)*1.053*1.65 -> 96341.076 | H24: =(H18-H23/1.1)*1.053*1.65 -> 93259.998 | I24: =(I18-I23/1.1)*1.053*1.65 -> 90221.04 | J24: =(J18-J23/1.1)*1.053*1.65 -> 86940.734 | ... AM24: =(AM18-AM23/1.1)*1.053*1.65 -> 26464.838
A25: 短流程废钢消耗量(万吨) | B25: 铁素资源公式 | C25: =C19*1.1 -> 11055.99 | D25: =D19*1.1 -> 11273.504 | E25: =E19*1.1 -> 11594 | F25: =F19*1.1 -> 12012 | G25: =G19*1.1 -> 12400.667 | H25: =H19*1.1 -> 12760 | I25: =I19*1.1 -> 13090 | J25: =J19*1.1 -> 13961.2 | ... AM25: =AM19*1.1 -> 32524.8 | AP25: ---电力参数---
A26: 氢冶金废钢消耗量(万吨) | B26: 铁素资源公式 | C26: =C20*0.5 -> 502.545 | D26: =D20*0.5 -> 560.4725 | E26: =E20*0.5 -> 620 | F26: =F20*0.5 -> 682.5 | G26: =G20*0.5 -> 741.66667 | H26: =H20*0.5 -> 797.5 | I26: =I20*0.5 -> 850 | J26: =J20*0.5 -> 1002 | ... AM26: =AM20*0.5 -> 5544 | AP26: 电网因子(kgCO2/kWh) | AQ26: 0.5306
A27: 氢冶金矿石消耗量(万吨) | B27: 铁素资源公式 | C27: =(C20-C26/1.1)*1.053*1.65 -> 952.52379 | D27: =(D20-D26/1.1)*1.053*1.65 -> 1062.3196 | E27: =(E20-E26/1.1)*1.053*1.65 -> 1175.148 | F27: =(F20-F26/1.1)*1.053*1.65 -> 1293.6105 | G27: =(G20-G26/1.1)*1.053*1.65 -> 1405.755 | H27: =(H20-H26/1.1)*1.053*1.65 -> 1511.5815 | I27: =(I20-I26/1.1)*1.053*1.65 -> 1611.09 | J27: =(J20-J26/1.1)*1.053*1.65 -> 1899.1908 | ... AM27: =(AM20-AM26/1.1)*1.053*1.65 -> 10508.098
A28: 废钢消耗总量(万吨) | B28: 铁素资源公式 | C28: =C23+C25+C26 -> 38394.438 | D28: =D23+D25+D26 -> 37247.401 | E28: =E23+E25+E26 -> 36580 | F28: =F23+F25+F26 -> 36309 | G28: =G23+G25+G26 -> 36015.333 | H28: =H23+H25+H26 -> 35699 | I28: =I23+I25+I26 -> 35360 | J28: =J23+J25+J26 -> 35604.4 | ... AM28: =AM23+AM25+AM26 -> 44352 | AP28: BF-BOF耗电(kWh/t) | AQ28: 450
A29: 矿石消耗总量(万吨) | B29: 铁素资源公式 | C29: =C24+C27 -> 113985.35 | D29: =D24+D27 -> 108103.66 | E29: =E24+E27 -> 103804.74 | F29: =F24+F27 -> 100757.88 | G29: =G24+G27 -> 97746.831 | H29: =H24+H27 -> 94771.579 | I29: =I24+I27 -> 91832.13 | J29: =J24+J27 -> 88839.925 | ... AM29: =AM24+AM27 -> 36972.936 | AP29: Scrap-EAF耗电(kWh/t) | AQ29: 550
A30: Step 6: 电力结构 | AP30: DRI-EAF耗电(kWh/t) | AQ30: 500
A31: 总耗电量(万kWh) | B31: 电力结构公式 | C31: =C18*450+C19*550+C20*500 -> 46284394 | D31: =D18*450+D19*550+D20*500 -> 44317361 | E31: =E18*450+E19*550+E20*500 -> 42966000 | F31: =F18*450+F19*550+F20*500 -> 42110250 | G31: =G18*450+G19*550+G20*500 -> 41251500 | H31: =H18*450+H19*550+H20*500 -> 40389750 | I31: =I18*450+I19*550+I20*500 -> 39525000 | J31: =J18*450+J19*550+J20*500 -> 38944400 | ... AM31: =AM18*450+AM19*550+AM20*500 -> 31231200
A32: 绿电占比 | B32: 电力结构公式 | C32: 0 | D32: 0.033333333 | E32: 0.066666667 | F32: 0.1 | G32: 0.13333333 | H32: 0.16666667 | I32: 0.2 | J32: 0.23 | K32: 0.26 | L32: 0.29 | M32: 0.32 | N32: 0.35 | O32: 0.384 | P32: 0.418 | Q32: 0.452 | R32: 0.486 | S32: 0.52 | T32: 0.54 | U32: 0.56 | V32: 0.58 | W32: 0.6 | X32: 0.62 | Y32: 0.64 | Z32: 0.66 | AA32: 0.68 | AB32: 0.7 | AC32: 0.72 | AD32: 0.736 | AE32: 0.752 | AF32: 0.768 | AG32: 0.784 | AH32: 0.8 | AI32: 0.816 | AJ32: 0.832 | AK32: 0.848 | AL32: 0.864 | AM32: 0.88
A33: 总绿电量(万kWh) | B33: 电力结构公式 | C33: =C31*C32 -> 0 | D33: =D31*D32 -> 1477245.4 | E33: =E31*E32 -> 2864400 | F33: =F31*F32 -> 4211025 | G33: =G31*G32 -> 5500200 | H33: =H31*H32 -> 6731625 | I33: =I31*I32 -> 7905000 | J33: =J31*J32 -> 8957212 | ... AM33: =AM31*AM32 -> 27483456
A34: Step 7: 低碳技术
A35: 低碳技术名称 | B35: 逐年技术部署 | C35: 干熄焦技术(已部署,含于基准) | D35: 厚料层烧结技术 | E35: 球团废热循环利用技术 | F35: - | G35: 高炉炉顶煤气干式余压发电技术(TRT) | H35: 高炉冲渣水直接换热回收余热技术 | I35: - | J35: 转炉气体及显热回收技术 | K35: 转炉'负能炼钢'工艺技术 | L35: 钢包加盖技术 | M35: 钢包周转优化技术 | N35: 废钢预热技术 | O35: 电源及电控系统智能化控制技术 | P35: 电炉连续加料技术 | Q35: - | R35: - | S35: - | T35: - | U35: - | V35: 连铸坯热送热装技术 | W35: - | X35: - | Y35: - | Z35: 薄板坯连铸技术 | AA35: - | AB35: - | AC35: - | AD35: - | AE35: - | AF35: - | AG35: - | AH35: - | AI35: - | AJ35: - | AK35: - | AL35: - | AM35: -
A36: 当年降碳潜力(tCO2/t) | B36: 逐年假设(可调) | C36: 0 | D36: 0.00083333333 | E36: 0.0016666667 | F36: 0.0025 | G36: 0.0033333333 | H36: 0.0041666667 | I36: 0.005 | J36: 0.008 | K36: 0.011 | L36: 0.014 | M36: 0.017 | N36: 0.02 | O36: 0.022 | P36: 0.024 | Q36: 0.026 | R36: 0.028 | S36: 0.03 | T36: 0.0305 | U36: 0.031 | V36: 0.0315 | W36: 0.032 | X36: 0.0325 | Y36: 0.033 | Z36: 0.0335 | AA36: 0.034 | AB36: 0.0345 | AC36: 0.035 | AD36: 0.0335 | AE36: 0.032 | AF36: 0.0305 | AG36: 0.029 | AH36: 0.0275 | AI36: 0.026 | AJ36: 0.0245 | AK36: 0.023 | AL36: 0.0215 | AM36: 0.02
A37: 累计降碳潜力(tCO2/t) | B37: =上年累计+当年新增 -> #NAME? | C37: =C36 -> 0 | D37: =C37+D36 -> 0.00083333333 | E37: =D37+E36 -> 0.0025 | F37: =E37+F36 -> 0.005 | G37: =F37+G36 -> 0.0083333333 | H37: =G37+H36 -> 0.0125 | I37: =H37+I36 -> 0.0175 | J37: =I37+J36 -> 0.0255 | K37: =J37+K36 -> 0.0365 | ... AM37: =AL37+AM36 -> 0.8125
A38: 原始累计(含基准1.95内) | B38: =模型累计+0.066 -> #NAME? | C38: =C37+0.066 -> 0.066 | D38: =D37+0.066 -> 0.066833333 | E38: =E37+0.066 -> 0.0685 | F38: =F37+0.066 -> 0.071 | G38: =G37+0.066 -> 0.074333333 | H38: =H37+0.066 -> 0.0785 | I38: =I37+0.066 -> 0.0835 | J38: =J37+0.066 -> 0.0915 | ... AM38: =AM37+0.066 -> 0.8785
A39: Step 8: 低碳发展测算表(Waterfall)
A40: 8.1 产量变化
A41: 产量变化碳排放曲线(万吨CO2) | B41: =粗钢产量×1.95 -> #NAME? | C41: =C13*1.95 -> 195992.55 | D41: =D13*1.95 -> 187357.95 | E41: =E13*1.95 -> 181350 | F41: =F13*1.95 -> 177450 | G41: =G13*1.95 -> 173550 | H41: =H13*1.95 -> 169650 | I41: =I13*1.95 -> 165750 | J41: =J13*1.95 -> 162825 | ... AM41: =AM13*1.95 -> 120120
...

Sheet 适度情景
A1: 钢铁行业减碳基准路径 - 适度情景
A2: 基准年2024 | 碳强度1.95 tCO2/t | CCUS百万吨起步 | 2024-2060逐年
A4: 指标 | B4: 公式说明 | C4: 2024 | D4: 2025 | E4: 2026 | F4: 2027 | G4: 2028 | H4: 2029 | I4: 2030 | J4: 2031 | K4: 2032 | L4: 2033 | M4: 2034 | N4: 2035 | O4: 2036 | P4: 2037 | Q4: 2038 | R4: 2039 | S4: 2040 | T4: 2041 | U4: 2042 | V4: 2043 | W4: 2044 | X4: 2045 | Y4: 2046 | Z4: 2047 | AA4: 2048 | AB4: 2049 | AC4: 2050 | AD4: 2051 | AE4: 2052 | AF4: 2053 | AG4: 2054 | AH4: 2055 | AI4: 2056 | AJ4: 2057 | AK4: 2058 | AL4: 2059 | AM4: 2060 | AP4: Step 2: 基准年参数
A5: Step 1: 宏观经济假设 | AP5: 参数名称 | AQ5: 参数值
A6: GDP增长率(%) | B6: 国家统计局/IFS-CGE | C6: 4.9 | D6: 4.5 | E6: 4.3 | F6: 4.1 | G6: 3.9 | H6: 3.7 | I6: 3.5 | J6: 3.3 | K6: 3.1 | L6: 3 | M6: 2.8 | N6: 2.7 | O6: 2.5 | P6: 2.4 | Q6: 2.2 | R6: 2.1 | S6: 2 | T6: 1.8 | U6: 1.7 | V6: 1.6 | W6: 1.5 | X6: 1.5 | Y6: 1.3 | Z6: 1.2 | AA6: 1.1 | AB6: 1 | AC6: 1 | AD6: 0.8 | AE6: 0.7 | AF6: 0.6 | AG6: 0.6 | AH6: 0.5 | AI6: 0.4 | AJ6: 0.4 | AK6: 0.3 | AL6: 0.3 | AM6: 0.2 | AP6: 基准年 | AQ6: 2024
A7: 实际GDP(2020价万亿) | B7: 支出法GDP | C7: 124.92 | D7: 130.54 | E7: 135.62767 | F7: 140.91362 | G7: 146.40559 | H7: 152.1116 | I7: 158.04 | J7: 162.7489 | K7: 167.59811 | L7: 172.59181 | M7: 177.73429 | N7: 183.03 | O7: 187.13014 | P7: 191.32213 | Q7: 195.60803 | R7: 199.98993 | S7: 204.47 | T7: 207.27266 | U7: 210.11373 | V7: 212.99374 | W7: 215.91323 | X7: 218.87274 | Y7: 221.87281 | Z7: 224.91401 | AA7: 227.99689 | AB7: 231.12203 | AC7: 234.29 | AD7: 235.41536 | AE7: 236.54613 | AF7: 237.68233 | AG7: 238.82398 | AH7: 239.97112 | AI7: 241.12377 | AJ7: 242.28196 | AK7: 243.44571 | AL7: 244.61504 | AM7: 245.79 | AP7: 粗钢产量(万吨) | AQ7: 100,509
A8: 人口(亿人) | B8: 联合国中位预测 | C8: 14.08 | D8: 14.08 | E8: 14.053903 | F8: 14.027855 | G8: 14.001855 | H8: 13.975904 | I8: 13.95 | J8: 13.909769 | K8: 13.869653 | L8: 13.829654 | M8: 13.789769 | N8: 13.75 | O8: 13.699632 | P8: 13.649449 | Q8: 13.59945 | R8: 13.549634 | S8: 13.5 | T8: 13.434592 | U8: 13.369501 | V8: 13.304726 | W8: 13.240264 | X8: 13.176115 | Y8: 13.112276 | Z8: 13.048747 | AA8: 12.985525 | AB8: 12.92261 | AC8: 12.86 | AD8: 12.782956 | AE8: 12.706373 | AF8: 12.630249 | AG8: 12.554581 | AH8: 12.479367 | AI8: 12.404603 | AJ8: 12.330287 | AK8: 12.256416 | AL8: 12.182988 | AM8: 12.11 | AP8: 碳排放总量(万吨CO2) | AQ8: 195,992
A9: 全国CO2排放(亿吨) | B9: IFS-CGE模型 | C9: 106.5 | D9: 108 | E9: 110 | F9: 112 | G9: 115 | H9: 117 | I9: 118 | J9: 117 | K9: 115.5 | L9: 113.5 | M9: 111 | N9: 109 | O9: 106.5 | P9: 103.5 | Q9: 100 | R9: 96 | S9: 92 | T9: 87.5 | U9: 83 | V9: 78.5 | W9: 74 | X9: 69.5 | Y9: 65 | Z9: 60.5 | AA9: 56 | AB9: 51.5 | AC9: 47 | AD9: 43 | AE9: 39 | AF9: 35.5 | AG9: 32 | AH9: 29 | AI9: 26.5 | AJ9: 24.5 | AK9: 23 | AL9: 22 | AM9: 21 | AP9: 吨钢碳排放强度(tCO2/t) | AQ9: 1.95
A10: 吨钢综合能耗(kgce/t) | B10: 2025+1.9%: 产品结构调整+超低排放+入炉矿品位下降 | C10: 1.85 | D10: 1.88515 | E10: 1.8757242 | F10: 1.8607185 | G10: 1.8421113 | H10: 1.8200059 | I10: 1.7927058 | J10: 1.7658153 | K10: 1.739328 | L10: 1.7132381 | M10: 1.6875395 | N10: 1.6622264 | O10: 1.6422797 | P10: 1.6225724 | Q10: 1.6031015 | R10: 1.5838643 | S10: 1.5680256 | T10: 1.5523454 | U10: 1.5368219 | V10: 1.5214537 | W10: 1.5092821 | X10: 1.4972078 | Y10: 1.4852302 | Z10: 1.4733483 | AA10: 1.4645082 | AB10: 1.4557212 | AC10: 1.4469869 | AD10: 1.4397519 | AE10: 1.4325532 | AF10: 1.4253904 | AG10: 1.4182634 | AH10: 1.4125904 | AI10: 1.40694 | AJ10: 1.4013123 | AK10: 1.3971083 | AL10: 1.392917 | AM10: 1.3887383
A11: 吨钢综合能耗同比变化(%) | B11: 国家统计局/中钢协数据 | C11: 0 | D11: 1.9 | E11: -0.5 | F11: -0.8 | G11: -1 | H11: -1.2 | I11: -1.5 | J11: -1.5 | K11: -1.5 | L11: -1.5 | M11: -1.5 | N11: -1.5 | O11: -1.2 | P11: -1.2 | Q11: -1.2 | R11: -1.2 | S11: -1 | T11: -1 | U11: -1 | V11: -1 | W11: -0.8 | X11: -0.8 | Y11: -0.8 | Z11: -0.8 | AA11: -0.6 | AB11: -0.6 | AC11: -0.6 | AD11: -0.5 | AE11: -0.5 | AF11: -0.5 | AG11: -0.5 | AH11: -0.4 | AI11: -0.4 | AJ11: -0.4 | AK11: -0.3 | AL11: -0.3 | AM11: -0.3 | AP11: ---工艺参数---
A12: Step 3: 粗钢产量(万吨) | AP12: 长流程产量占比(%) | AQ12: 89
A13: 粗钢产量(万吨) | B13: CAGR插值(三情景共用) | C13: 100509 | D13: 96081 | E13: 94000 | F13: 92500 | G13: 91000 | H13: 89500 | I13: 88000 | J13: 86800 | K13: 85600 | L13: 84400 | M13: 83200 | N13: 82000 | O13: 81200 | P13: 80500 | Q13: 79800 | R13: 79200 | S13: 78600 | T13: 78000 | U13: 77400 | V13: 76800 | W13: 76200 | X13: 75600 | Y13: 75000 | Z13: 74500 | AA13: 74000 | AB13: 73500 | AC13: 73000 | AD13: 72300 | AE13: 71600 | AF13: 70900 | AG13: 70200 | AH13: 69500 | AI13: 68800 | AJ13: 68200 | AK13: 67600 | AL13: 67100 | AM13: 66600 | AP13: 短流程产量占比(%) | AQ13: 10
A14: Step 4: 流程结构 | AP14: 氢冶金产量占比(%) | AQ14: 1
A15: 短流程产量占比(%) | B15: 二分法校准 | C15: 10 | D15: 10.333333 | E15: 10.666667 | F15: 11 | G15: 11.333333 | H15: 11.666667 | I15: 12 | J15: 12.8 | K15: 13.6 | L15: 14.4 | M15: 15.2 | N15: 16 | O15: 17.2 | P15: 18.4 | Q15: 19.6 | R15: 20.8 | S15: 22 | T15: 23 | U15: 24 | V15: 25 | W15: 26 | X15: 27 | Y15: 28 | Z15: 29 | AA15: 30 | AB15: 31 | AC15: 32 | AD15: 33 | AE15: 34 | AF15: 35 | AG15: 36 | AH15: 37 | AI15: 38 | AJ15: 39 | AK15: 40 | AL15: 41 | AM15: 42
A16: 氢冶金产量占比(%) | B16: 情景差异化 | C16: 1 | D16: 1.1333333 | E16: 1.2666667 | F16: 1.4 | G16: 1.5333333 | H16: 1.6666667 | I16: 1.8 | J16: 2.04 | K16: 2.28 | L16: 2.52 | M16: 2.76 | N16: 3 | O16: 3.6 | P16: 4.2 | Q16: 4.8 | R16: 5.4 | S16: 6 | T16: 6.5 | U16: 7 | V16: 7.5 | W16: 8 | X16: 8.5 | Y16: 9 | Z16: 9.5 | AA16: 10 | AB16: 10.5 | AC16: 11 | AD16: 11.4 | AE16: 11.8 | AF16: 12.2 | AG16: 12.6 | AH16: 13 | AI16: 13.4 | AJ16: 13.8 | AK16: 14.2 | AL16: 14.6 | AM16: 15 | AP16: 吨钢耗废钢量 | AQ16: 1.1
A17: 长流程产量占比(%) | B17: =1-短流程%-氢冶金% -> #NAME? | C17: =1-C15/100-C16/100 -> 0.89 | D17: =1-D15/100-D16/100 -> 0.88533333 | E17: =1-E15/100-E16/100 -> 0.88066667 | F17: =1-F15/100-F16/100 -> 0.876 | G17: =1-G15/100-G16/100 -> 0.87133333 | H17: =1-H15/100-H16/100 -> 0.86666667 | I17: =1-I15/100-I16/100 -> 0.862 | J17: =1-J15/100-J16/100 -> 0.8516 | ... AM17: =1-AM15/100-AM16/100 -> 0.43 | AP17: 吨钢耗铁水量 | AQ17: 1.053
A18: 长流程产量(万吨) | B18: =长流程产量公式 -> #NAME? | C18: =C13*C17 -> 89453.01 | D18: =D13*D17 -> 85063.712 | E18: =E13*E17 -> 82782.667 | F18: =F13*F17 -> 81030 | G18: =G13*G17 -> 79291.333 | H18: =H13*H17 -> 77566.667 | I18: =I13*I17 -> 75856 | J18: =J13*J17 -> 73918.88 | ... AM18: =AM13*AM17 -> 28638 | AP18: 吨铁水耗铁矿石量 | AQ18: 1.65
A19: 短流程产量(万吨) | B19: =短流程产量公式 -> #NAME? | C19: =C13*C15/100 -> 10050.9 | D19: =D13*D15/100 -> 9928.37 | E19: =E13*E15/100 -> 10026.667 | F19: =F13*F15/100 -> 10175 | G19: =G13*G15/100 -> 10313.333 | H19: =H13*H15/100 -> 10441.667 | I19: =I13*I15/100 -> 10560 | J19: =J13*J15/100 -> 11110.4 | ... AM19: =AM13*AM15/100 -> 27972
A20: 氢冶金产量(万吨) | B20: =氢冶金产量公式 -> #NAME? | C20: =C13*C16/100 -> 1005.09 | D20: =D13*D16/100 -> 1088.918 | E20: =E13*E16/100 -> 1190.6667 | F20: =F13*F16/100 -> 1295 | G20: =G13*G16/100 -> 1395.3333 | H20: =H13*H16/100 -> 1491.6667 | I20: =I13*I16/100 -> 1584 | J20: =J13*J16/100 -> 1770.72 | ... AM20: =AM13*AM16/100 -> 9990 | AP20: BF-BOF碳排放强度 | AQ20: 1.80 tCO2/t
A21: Step 5: 铁素资源结构 | AP21: Scrap-EAF碳排放强度 | AQ21: 0.45 tCO2/t
A22: 废钢资源量参考(万吨/年) | B22: 崔志峰等(2023): 2045峰值约5亿吨, 2050年4.7-5.2亿吨 | C22: 28808 | D22: 28229 | E22: 29969 | F22: 29387 | G22: 29387 | H22: 28789 | I22: 32769 | J22: 34491 | K22: 36732 | L22: 37921 | M22: 40610 | N22: 41361 | O22: 39766 | P22: 40502 | Q22: 43587 | R22: 48920 | S22: 49354 | T22: 53285 | U22: 53684 | V22: 57951 | W22: 57041 | X22: 57897 | Y22: 58206 | Z22: 58406 | AA22: 58447 | AB22: 58384 | AC22: 58168 | AD22: 57730 | AE22: 57366 | AF22: 57787 | AG22: 57476 | AH22: 57995 | AI22: 56989 | AJ22: 55995 | AK22: 55102 | AL22: 54192 | AM22: 53288 | AP22: DRI-EAF碳排放强度 | AQ22: 1.65 tCO2/t
A23: 长流程废钢消耗量(万吨) | B23: 铁素资源公式 | C23: =C18*0.3 -> 26835.903 | D23: =D18*0.3 -> 25519.114 | E23: =E18*0.3 -> 24834.8 | F23: =F18*0.3 -> 24309 | G23: =G18*0.3 -> 23787.4 | H23: =H18*0.3 -> 23270 | I23: =I18*0.3 -> 22756.8 | J23: =J18*0.3 -> 22175.664 | ... AM23: =AM18*0.3 -> 8591.4 | AP23: 铁水碳排放强度 | AQ23: 1.26 tCO2/t
A24: 长流程矿石消耗量(万吨) | B24: 铁素资源公式 | C24: =(C18-C23/1.1)*1.053*1.65 -> 113032.82 | D24: =(D18-D23/1.1)*1.053*1.65 -> 107486.51 | E24: =(E18-E23/1.1)*1.053*1.65 -> 104604.18 | F24: =(F18-F23/1.1)*1.053*1.65 -> 102389.51 | G24: =(G18-G23/1.1)*1.053*1.65 -> 100192.53 | H24: =(H18-H23/1.1)*1.053*1.65 -> 98013.24 | I24: =(I18-I23/1.1)*1.053*1.65 -> 95851.642 | J24: =(J18-J23/1.1)*1.053*1.65 -> 93403.897 | ... AM24: =(AM18-AM23/1.1)*1.053*1.65 -> 36186.977
A25: 短流程废钢消耗量(万吨) | B25: 铁素资源公式 | C25: =C19*1.1 -> 11055.99 | D25: =D19*1.1 -> 10921.207 | E25: =E19*1.1 -> 11029.333 | F25: =F19*1.1 -> 11192.5 | G25: =G19*1.1 -> 11344.667 | H25: =H19*1.1 -> 11485.833 | I25: =I19*1.1 -> 11616 | J25: =J19*1.1 -> 12221.44 | ... AM25: =AM19*1.1 -> 30769.2 | AP25: ---电力参数---
A26: 氢冶金废钢消耗量(万吨) | B26: 铁素资源公式 | C26: =C20*0.5 -> 502.545 | D26: =D20*0.5 -> 544.459 | E26: =E20*0.5 -> 595.33333 | F26: =F20*0.5 -> 647.5 | G26: =G20*0.5 -> 697.66667 | H26: =H20*0.5 -> 745.83333 | I26: =I20*0.5 -> 792 | J26: =J20*0.5 -> 885.36 | ... AM26: =AM20*0.5 -> 4995 | AP26: 电网因子(kgCO2/kWh) | AQ26: 0.5306
A27: 氢冶金矿石消耗量(万吨) | B27: 铁素资源公式 | C27: =(C20-C26/1.1)*1.053*1.65 -> 952.52379 | D27: =(D20-D26/1.1)*1.053*1.65 -> 1031.9676 | E27: =(E20-E26/1.1)*1.053*1.65 -> 1128.3948 | F27: =(F20-F26/1.1)*1.053*1.65 -> 1227.2715 | G27: =(G20-G26/1.1)*1.053*1.65 -> 1322.3574 | H27: =(H20-H26/1.1)*1.053*1.65 -> 1413.6525 | I27: =(I20-I26/1.1)*1.053*1.65 -> 1501.1568 | J27: =(J20-J26/1.1)*1.053*1.65 -> 1678.1113 | ... AM27: =(AM20-AM26/1.1)*1.053*1.65 -> 9467.523
A28: 废钢消耗总量(万吨) | B28: 铁素资源公式 | C28: =C23+C25+C26 -> 38394.438 | D28: =D23+D25+D26 -> 36984.78 | E28: =E23+E25+E26 -> 36459.467 | F28: =F23+F25+F26 -> 36149 | G28: =G23+G25+G26 -> 35829.733 | H28: =H23+H25+H26 -> 35501.667 | I28: =I23+I25+I26 -> 35164.8 | J28: =J23+J25+J26 -> 35282.464 | ... AM28: =AM23+AM25+AM26 -> 44355.6 | AP28: BF-BOF耗电(kWh/t) | AQ28: 450
A29: 矿石消耗总量(万吨) | B29: 铁素资源公式 | C29: =C24+C27 -> 113985.35 | D29: =D24+D27 -> 108518.47 | E29: =E24+E27 -> 105732.57 | F29: =F24+F27 -> 103616.78 | G29: =G24+G27 -> 101514.89 | H29: =H24+H27 -> 99426.892 | I29: =I24+I27 -> 97352.798 | J29: =J24+J27 -> 95082.008 | ... AM29: =AM24+AM27 -> 45654.5 | AP29: Scrap-EAF耗电(kWh/t) | AQ29: 550
A30: Step 6: 电力结构 | AP30: DRI-EAF耗电(kWh/t) | AQ30: 500
A31: 总耗电量(万kWh) | B31: 电力结构公式 | C31: =C18*450+C19*550+C20*500 -> 46284394 | D31: =D18*450+D19*550+D20*500 -> 44283733 | E31: =E18*450+E19*550+E20*500 -> 43362200 | F31: =F18*450+F19*550+F20*500 -> 42707250 | G31: =G18*450+G19*550+G20*500 -> 42051100 | H31: =H18*450+H19*550+H20*500 -> 41393750 | I31: =I18*450+I19*550+I20*500 -> 40735200 | J31: =J18*450+J19*550+J20*500 -> 40259576 | ... AM31: =AM18*450+AM19*550+AM20*500 -> 33266700
A32: 绿电占比 | B32: 电力结构公式 | C32: 0 | D32: 0.025 | E32: 0.05 | F32: 0.075 | G32: 0.1 | H32: 0.125 | I32: 0.15 | J32: 0.176 | K32: 0.202 | L32: 0.228 | M32: 0.254 | N32: 0.28 | O32: 0.314 | P32: 0.348 | Q32: 0.382 | R32: 0.416 | S32: 0.45 | T32: 0.468 | U32: 0.486 | V32: 0.504 | W32: 0.522 | X32: 0.54 | Y32: 0.558 | Z32: 0.576 | AA32: 0.594 | AB32: 0.612 | AC32: 0.63 | AD32: 0.649 | AE32: 0.668 | AF32: 0.687 | AG32: 0.706 | AH32: 0.725 | AI32: 0.744 | AJ32: 0.763 | AK32: 0.782 | AL32: 0.801 | AM32: 0.82
A33: 总绿电量(万kWh) | B33: 电力结构公式 | C33: =C31*C32 -> 0 | D33: =D31*D32 -> 1107093.3 | E33: =E31*E32 -> 2168110 | F33: =F31*F32 -> 3203043.8 | G33: =G31*G32 -> 4205110 | H33: =H31*H32 -> 5174218.7 | I33: =I31*I32 -> 6110280 | J33: =J31*J32 -> 7085685.4 | ... AM33: =AM31*AM32 -> 27278694
A34: Step 7: 低碳技术
A35: 低碳技术名称 | B35: 逐年技术部署 | C35: 干熄焦技术(已部署,含于基准) | D35: 厚料层烧结技术 | E35: 球团废热循环利用技术 | F35: - | G35: 高炉炉顶煤气干式余压发电技术(TRT) | H35: 高炉冲渣水直接换热回收余热技术 | I35: - | J35: 转炉气体及显热回收技术 | K35: 转炉'负能炼钢'工艺技术 | L35: 钢包加盖技术 | M35: 钢包周转优化技术 | N35: 废钢预热技术 | O35: 电源及电控系统智能化控制技术 | P35: 电炉连续加料技术 | Q35: - | R35: - | S35: - | T35: - | U35: - | V35: 连铸坯热送热装技术 | W35: - | X35: - | Y35: - | Z35: 薄板坯连铸技术 | AA35: - | AB35: - | AC35: - | AD35: - | AE35: - | AF35: - | AG35: - | AH35: - | AI35: - | AJ35: - | AK35: - | AL35: - | AM35: -
A36: 当年降碳潜力(tCO2/t) | B36: 逐年假设(可调) | C36: 0 | D36: 0.00066666667 | E36: 0.0013333333 | F36: 0.002 | G36: 0.0026666667 | H36: 0.0033333333 | I36: 0.004 | J36: 0.0062 | K36: 0.0084 | L36: 0.0106 | M36: 0.0128 | N36: 0.015 | O36: 0.017 | P36: 0.019 | Q36: 0.021 | R36: 0.023 | S36: 0.025 | T36: 0.0255 | U36: 0.026 | V36: 0.0265 | W36: 0.027 | X36: 0.0275 | Y36: 0.028 | Z36: 0.0285 | AA36: 0.029 | AB36: 0.0295 | AC36: 0.03 | AD36: 0.0288 | AE36: 0.0276 | AF36: 0.0264 | AG36: 0.0252 | AH36: 0.024 | AI36: 0.0228 | AJ36: 0.0216 | AK36: 0.0204 | AL36: 0.0192 | AM36: 0.018
A37: 累计降碳潜力(tCO2/t) | B37: =上年累计+当年新增 -> #NAME? | C37: =C36 -> 0 | D37: =C37+D36 -> 0.00066666667 | E37: =D37+E36 -> 0.002 | F37: =E37+F36 -> 0.004 | G37: =F37+G36 -> 0.0066666667 | H37: =G37+H36 -> 0.01 | I37: =H37+I36 -> 0.014 | J37: =I37+J36 -> 0.0202 | K37: =J37+K36 -> 0.0286 | ... AM37: =AL37+AM36 -> 0.6835
A38: 原始累计(含基准1.95内) | B38: =模型累计+0.066 -> #NAME? | C38: =C37+0.066 -> 0.066 | D38: =D37+0.066 -> 0.066666667 | E38: =E37+0.066 -> 0.068 | F38: =F37+0.066 -> 0.07 | G38: =G37+0.066 -> 0.072666667 | H38: =H37+0.066 -> 0.076 | I38: =I37+0.066 -> 0.08 | J38: =J37+0.066 -> 0.0862 | ... AM38: =AM37+0.066 -> 0.7495
A39: Step 8: 低碳发展测算表(Waterfall)
A40: 8.1 产量变化
A41: 产量变化碳排放曲线(万吨CO2) | B41: =粗钢产量×1.95 -> #NAME? | C41: =C13*1.95 -> 195992.55 | D41: =D13*1.95 -> 187357.95 | E41: =E13*1.95 -> 183300 | F41: =F13*1.95 -> 180375 | G41: =G13*1.95 -> 177450 | H41: =H13*1.95 -> 174525 | I41: =I13*1.95 -> 171600 | J41: =J13*1.95 -> 169260 | ... AM41: =AM13*1.95 -> 129870
...

Sheet 保守情景
A1: 钢铁行业减碳基准路径 - 保守情景
A2: 基准年2024 | 碳强度1.95 tCO2/t | CCUS百万吨起步 | 2024-2060逐年
A4: 指标 | B4: 公式说明 | C4: 2024 | D4: 2025 | E4: 2026 | F4: 2027 | G4: 2028 | H4: 2029 | I4: 2030 | J4: 2031 | K4: 2032 | L4: 2033 | M4: 2034 | N4: 2035 | O4: 2036 | P4: 2037 | Q4: 2038 | R4: 2039 | S4: 2040 | T4: 2041 | U4: 2042 | V4: 2043 | W4: 2044 | X4: 2045 | Y4: 2046 | Z4: 2047 | AA4: 2048 | AB4: 2049 | AC4: 2050 | AD4: 2051 | AE4: 2052 | AF4: 2053 | AG4: 2054 | AH4: 2055 | AI4: 2056 | AJ4: 2057 | AK4: 2058 | AL4: 2059 | AM4: 2060 | AP4: Step 2: 基准年参数
A5: Step 1: 宏观经济假设 | AP5: 参数名称 | AQ5: 参数值
A6: GDP增长率(%) | B6: 国家统计局/IFS-CGE | C6: 4.9 | D6: 4.5 | E6: 4.3 | F6: 4.1 | G6: 3.9 | H6: 3.7 | I6: 3.5 | J6: 3.3 | K6: 3.1 | L6: 3 | M6: 2.8 | N6: 2.7 | O6: 2.5 | P6: 2.4 | Q6: 2.2 | R6: 2.1 | S6: 2 | T6: 1.8 | U6: 1.7 | V6: 1.6 | W6: 1.5 | X6: 1.5 | Y6: 1.3 | Z6: 1.2 | AA6: 1.1 | AB6: 1 | AC6: 1 | AD6: 0.8 | AE6: 0.7 | AF6: 0.6 | AG6: 0.6 | AH6: 0.5 | AI6: 0.4 | AJ6: 0.4 | AK6: 0.3 | AL6: 0.3 | AM6: 0.2 | AP6: 基准年 | AQ6: 2024
A7: 实际GDP(2020价万亿) | B7: 支出法GDP | C7: 124.92 | D7: 130.54 | E7: 135.62767 | F7: 140.91362 | G7: 146.40559 | H7: 152.1116 | I7: 158.04 | J7: 162.7489 | K7: 167.59811 | L7: 172.59181 | M7: 177.73429 | N7: 183.03 | O7: 187.13014 | P7: 191.32213 | Q7: 195.60803 | R7: 199.98993 | S7: 204.47 | T7: 207.27266 | U7: 210.11373 | V7: 212.99374 | W7: 215.91323 | X7: 218.87274 | Y7: 221.87281 | Z7: 224.91401 | AA7: 227.99689 | AB7: 231.12203 | AC7: 234.29 | AD7: 235.41536 | AE7: 236.54613 | AF7: 237.68233 | AG7: 238.82398 | AH7: 239.97112 | AI7: 241.12377 | AJ7: 242.28196 | AK7: 243.44571 | AL7: 244.61504 | AM7: 245.79 | AP7: 粗钢产量(万吨) | AQ7: 100,509
A8: 人口(亿人) | B8: 联合国中位预测 | C8: 14.08 | D8: 14.08 | E8: 14.053903 | F8: 14.027855 | G8: 14.001855 | H8: 13.975904 | I8: 13.95 | J8: 13.909769 | K8: 13.869653 | L8: 13.829654 | M8: 13.789769 | N8: 13.75 | O8: 13.699632 | P8: 13.649449 | Q8: 13.59945 | R8: 13.549634 | S8: 13.5 | T8: 13.434592 | U8: 13.369501 | V8: 13.304726 | W8: 13.240264 | X8: 13.176115 | Y8: 13.112276 | Z8: 13.048747 | AA8: 12.985525 | AB8: 12.92261 | AC8: 12.86 | AD8: 12.782956 | AE8: 12.706373 | AF8: 12.630249 | AG8: 12.554581 | AH8: 12.479367 | AI8: 12.404603 | AJ8: 12.330287 | AK8: 12.256416 | AL8: 12.182988 | AM8: 12.11 | AP8: 碳排放总量(万吨CO2) | AQ8: 195,992
A9: 全国CO2排放(亿吨) | B9: IFS-CGE模型 | C9: 106.5 | D9: 108 | E9: 110 | F9: 112 | G9: 115 | H9: 117 | I9: 118 | J9: 117 | K9: 115.5 | L9: 113.5 | M9: 111 | N9: 109 | O9: 106.5 | P9: 103.5 | Q9: 100 | R9: 96 | S9: 92 | T9: 87.5 | U9: 83 | V9: 78.5 | W9: 74 | X9: 69.5 | Y9: 65 | Z9: 60.5 | AA9: 56 | AB9: 51.5 | AC9: 47 | AD9: 43 | AE9: 39 | AF9: 35.5 | AG9: 32 | AH9: 29 | AI9: 26.5 | AJ9: 24.5 | AK9: 23 | AL9: 22 | AM9: 21 | AP9: 吨钢碳排放强度(tCO2/t) | AQ9: 1.95
A10: 吨钢综合能耗(kgce/t) | B10: 2025+1.9%: 产品结构调整+超低排放+入炉矿品位下降 | C10: 1.85 | D10: 1.88515 | E10: 1.8757242 | F10: 1.8607185 | G10: 1.8421113 | H10: 1.8200059 | I10: 1.7927058 | J10: 1.7658153 | K10: 1.739328 | L10: 1.7132381 | M10: 1.6875395 | N10: 1.6622264 | O10: 1.6422797 | P10: 1.6225724 | Q10: 1.6031015 | R10: 1.5838643 | S10: 1.5680256 | T10: 1.5523454 | U10: 1.5368219 | V10: 1.5214537 | W10: 1.5092821 | X10: 1.4972078 | Y10: 1.4852302 | Z10: 1.4733483 | AA10: 1.4645082 | AB10: 1.4557212 | AC10: 1.4469869 | AD10: 1.4397519 | AE10: 1.4325532 | AF10: 1.4253904 | AG10: 1.4182634 | AH10: 1.4125904 | AI10: 1.40694 | AJ10: 1.4013123 | AK10: 1.3971083 | AL10: 1.392917 | AM10: 1.3887383
A11: 吨钢综合能耗同比变化(%) | B11: 国家统计局/中钢协数据 | C11: 0 | D11: 1.9 | E11: -0.5 | F11: -0.8 | G11: -1 | H11: -1.2 | I11: -1.5 | J11: -1.5 | K11: -1.5 | L11: -1.5 | M11: -1.5 | N11: -1.5 | O11: -1.2 | P11: -1.2 | Q11: -1.2 | R11: -1.2 | S11: -1 | T11: -1 | U11: -1 | V11: -1 | W11: -0.8 | X11: -0.8 | Y11: -0.8 | Z11: -0.8 | AA11: -0.6 | AB11: -0.6 | AC11: -0.6 | AD11: -0.5 | AE11: -0.5 | AF11: -0.5 | AG11: -0.5 | AH11: -0.4 | AI11: -0.4 | AJ11: -0.4 | AK11: -0.3 | AL11: -0.3 | AM11: -0.3 | AP11: ---工艺参数---
A12: Step 3: 粗钢产量(万吨) | AP12: 长流程产量占比(%) | AQ12: 89
A13: 粗钢产量(万吨) | B13: CAGR插值(三情景共用) | C13: 100509 | D13: 96081 | E13: 95000 | F13: 94000 | G13: 93000 | H13: 92000 | I13: 91000 | J13: 90000 | K13: 89000 | L13: 87800 | M13: 86600 | N13: 85500 | O13: 84800 | P13: 84200 | Q13: 83600 | R13: 83100 | S13: 82600 | T13: 82200 | U13: 81800 | V13: 81500 | W13: 81200 | X13: 80900 | Y13: 80600 | Z13: 80300 | AA13: 79800 | AB13: 79200 | AC13: 78500 | AD13: 77900 | AE13: 77300 | AF13: 76700 | AG13: 76100 | AH13: 75500 | AI13: 75000 | AJ13: 74500 | AK13: 74000 | AL13: 73500 | AM13: 73100 | AP13: 短流程产量占比(%) | AQ13: 10
A14: Step 4: 流程结构 | AP14: 氢冶金产量占比(%) | AQ14: 1
A15: 短流程产量占比(%) | B15: 二分法校准 | C15: 10 | D15: 10.083333 | E15: 10.166667 | F15: 10.25 | G15: 10.333333 | H15: 10.416667 | I15: 10.5 | J15: 10.8 | K15: 11.1 | L15: 11.4 | M15: 11.7 | N15: 12 | O15: 12.8 | P15: 13.6 | Q15: 14.4 | R15: 15.2 | S15: 16 | T15: 16.8 | U15: 17.6 | V15: 18.4 | W15: 19.2 | X15: 20 | Y15: 20.8 | Z15: 21.6 | AA15: 22.4 | AB15: 23.2 | AC15: 24 | AD15: 25 | AE15: 26 | AF15: 27 | AG15: 28 | AH15: 29 | AI15: 30 | AJ15: 31 | AK15: 32 | AL15: 33 | AM15: 34
A16: 氢冶金产量占比(%) | B16: 情景差异化 | C16: 1 | D16: 1.0833333 | E16: 1.1666667 | F16: 1.25 | G16: 1.3333333 | H16: 1.4166667 | I16: 1.5 | J16: 1.7 | K16: 1.9 | L16: 2.1 | M16: 2.3 | N16: 2.5 | O16: 2.8 | P16: 3.1 | Q16: 3.4 | R16: 3.7 | S16: 4 | T16: 4.4 | U16: 4.8 | V16: 5.2 | W16: 5.6 | X16: 6 | Y16: 6.4 | Z16: 6.8 | AA16: 7.2 | AB16: 7.6 | AC16: 8 | AD16: 8.4 | AE16: 8.8 | AF16: 9.2 | AG16: 9.6 | AH16: 10 | AI16: 10.4 | AJ16: 10.8 | AK16: 11.2 | AL16: 11.6 | AM16: 12 | AP16: 吨钢耗废钢量 | AQ16: 1.1
A17: 长流程产量占比(%) | B17: =1-短流程%-氢冶金% -> #NAME? | C17: =1-C15/100-C16/100 -> 0.89 | D17: =1-D15/100-D16/100 -> 0.88833333 | E17: =1-E15/100-E16/100 -> 0.88666667 | F17: =1-F15/100-F16/100 -> 0.885 | G17: =1-G15/100-G16/100 -> 0.88333333 | H17: =1-H15/100-H16/100 -> 0.88166667 | I17: =1-I15/100-I16/100 -> 0.88 | J17: =1-J15/100-J16/100 -> 0.875 | ... AM17: =1-AM15/100-AM16/100 -> 0.54 | AP17: 吨钢耗铁水量 | AQ17: 1.053
A18: 长流程产量(万吨) | B18: =长流程产量公式 -> #NAME? | C18: =C13*C17 -> 89453.01 | D18: =D13*D17 -> 85351.955 | E18: =E13*E17 -> 84233.333 | F18: =F13*F17 -> 83190 | G18: =G13*G17 -> 82150 | H18: =H13*H17 -> 81113.333 | I18: =I13*I17 -> 80080 | J18: =J13*J17 -> 78750 | ... AM18: =AM13*AM17 -> 39474 | AP18: 吨铁水耗铁矿石量 | AQ18: 1.65
A19: 短流程产量(万吨) | B19: =短流程产量公式 -> #NAME? | C19: =C13*C15/100 -> 10050.9 | D19: =D13*D15/100 -> 9688.1675 | E19: =E13*E15/100 -> 9658.3333 | F19: =F13*F15/100 -> 9635 | G19: =G13*G15/100 -> 9610 | H19: =H13*H15/100 -> 9583.3333 | I19: =I13*I15/100 -> 9555 | J19: =J13*J15/100 -> 9720 | ... AM19: =AM13*AM15/100 -> 24854
A20: 氢冶金产量(万吨) | B20: =氢冶金产量公式 -> #NAME? | C20: =C13*C16/100 -> 1005.09 | D20: =D13*D16/100 -> 1040.8775 | E20: =E13*E16/100 -> 1108.3333 | F20: =F13*F16/100 -> 1175 | G20: =G13*G16/100 -> 1240 | H20: =H13*H16/100 -> 1303.3333 | I20: =I13*I16/100 -> 1365 | J20: =J13*J16/100 -> 1530 | ... AM20: =AM13*AM16/100 -> 8772 | AP20: BF-BOF碳排放强度 | AQ20: 1.80 tCO2/t
A21: Step 5: 铁素资源结构 | AP21: Scrap-EAF碳排放强度 | AQ21: 0.45 tCO2/t
A22: 废钢资源量参考(万吨/年) | B22: 崔志峰等(2023): 2045峰值约5亿吨, 2050年4.7-5.2亿吨 | C22: 28826 | D22: 28254 | E22: 29999 | F22: 29431 | G22: 29435 | H22: 28841 | I22: 32825 | J22: 34566 | K22: 36824 | L22: 38029 | M22: 40733 | N22: 41498 | O22: 39919 | P22: 40670 | Q22: 43771 | R22: 49120 | S22: 49569 | T22: 53511 | U22: 53922 | V22: 58199 | W22: 57300 | X22: 58133 | Y22: 58418 | Z22: 58749 | AA22: 58819 | AB22: 58783 | AC22: 58648 | AD22: 58235 | AE22: 57897 | AF22: 58334 | AG22: 58048 | AH22: 58590 | AI22: 57706 | AJ22: 56824 | AK22: 56041 | AL22: 55228 | AM22: 54411 | AP22: DRI-EAF碳排放强度 | AQ22: 1.65 tCO2/t
A23: 长流程废钢消耗量(万吨) | B23: 铁素资源公式 | C23: =C18*0.3 -> 26835.903 | D23: =D18*0.3 -> 25605.587 | E23: =E18*0.3 -> 25270 | F23: =F18*0.3 -> 24957 | G23: =G18*0.3 -> 24645 | H23: =H18*0.3 -> 24334 | I23: =I18*0.3 -> 24024 | J23: =J18*0.3 -> 23625 | ... AM23: =AM18*0.3 -> 11842.2 | AP23: 铁水碳排放强度 | AQ23: 1.26 tCO2/t
A24: 长流程矿石消耗量(万吨) | B24: 铁素资源公式 | C24: =(C18-C23/1.1)*1.053*1.65 -> 113032.82 | D24: =(D18-D23/1.1)*1.053*1.65 -> 107850.73 | E24: =(E18-E23/1.1)*1.053*1.65 -> 106437.24 | F24: =(F18-F23/1.1)*1.053*1.65 -> 105118.88 | G24: =(G18-G23/1.1)*1.053*1.65 -> 103804.74 | H24: =(H18-H23/1.1)*1.053*1.65 -> 102494.81 | I24: =(I18-I23/1.1)*1.053*1.65 -> 101189.09 | J24: =(J18-J23/1.1)*1.053*1.65 -> 99508.5 | ... AM24: =(AM18-AM23/1.1)*1.053*1.65 -> 49879.346
A25: 短流程废钢消耗量(万吨) | B25: 铁素资源公式 | C25: =C19*1.1 -> 11055.99 | D25: =D19*1.1 -> 10656.984 | E25: =E19*1.1 -> 10624.167 | F25: =F19*1.1 -> 10598.5 | G25: =G19*1.1 -> 10571 | H25: =H19*1.1 -> 10541.667 | I25: =I19*1.1 -> 10510.5 | J25: =J19*1.1 -> 10692 | ... AM25: =AM19*1.1 -> 27339.4 | AP25: ---电力参数---
A26: 氢冶金废钢消耗量(万吨) | B26: 铁素资源公式 | C26: =C20*0.5 -> 502.545 | D26: =D20*0.5 -> 520.43875 | E26: =E20*0.5 -> 554.16667 | F26: =F20*0.5 -> 587.5 | G26: =G20*0.5 -> 620 | H26: =H20*0.5 -> 651.66667 | I26: =I20*0.5 -> 682.5 | J26: =J20*0.5 -> 765 | ... AM26: =AM20*0.5 -> 4386 | AP26: 电网因子(kgCO2/kWh) | AQ26: 0.5306
A27: 氢冶金矿石消耗量(万吨) | B27: 铁素资源公式 | C27: =(C20-C26/1.1)*1.053*1.65 -> 952.52379 | D27: =(D20-D26/1.1)*1.053*1.65 -> 986.43961 | E27: =(E20-E26/1.1)*1.053*1.65 -> 1050.3675 | F27: =(F20-F26/1.1)*1.053*1.65 -> 1113.5475 | G27: =(G20-G26/1.1)*1.053*1.65 -> 1175.148 | H27: =(H20-H26/1.1)*1.053*1.65 -> 1235.169 | I27: =(I20-I26/1.1)*1.053*1.65 -> 1293.6105 | J27: =(J20-J26/1.1)*1.053*1.65 -> 1449.981 | ... AM27: =(AM20-AM26/1.1)*1.053*1.65 -> 8313.2244
A28: 废钢消耗总量(万吨) | B28: 铁素资源公式 | C28: =C23+C25+C26 -> 38394.438 | D28: =D23+D25+D26 -> 36783.01 | E28: =E23+E25+E26 -> 36448.333 | F28: =F23+F25+F26 -> 36143 | G28: =G23+G25+G26 -> 35836 | H28: =H23+H25+H26 -> 35527.333 | I28: =I23+I25+I26 -> 35217 | J28: =J23+J25+J26 -> 35082 | ... AM28: =AM23+AM25+AM26 -> 43567.6 | AP28: BF-BOF耗电(kWh/t) | AQ28: 450
A29: 矿石消耗总量(万吨) | B29: 铁素资源公式 | C29: =C24+C27 -> 113985.35 | D29: =D24+D27 -> 108837.17 | E29: =E24+E27 -> 107487.61 | F29: =F24+F27 -> 106232.43 | G29: =G24+G27 -> 104979.89 | H29: =H24+H27 -> 103729.98 | I29: =I24+I27 -> 102482.7 | J29: =J24+J27 -> 100958.48 | ... AM29: =AM24+AM27 -> 58192.571 | AP29: Scrap-EAF耗电(kWh/t) | AQ29: 550
A30: Step 6: 电力结构 | AP30: DRI-EAF耗电(kWh/t) | AQ30: 500
A31: 总耗电量(万kWh) | B31: 电力结构公式 | C31: =C18*450+C19*550+C20*500 -> 46284394 | D31: =D18*450+D19*550+D20*500 -> 44257311 | E31: =E18*450+E19*550+E20*500 -> 43771250 | F31: =F18*450+F19*550+F20*500 -> 43322250 | G31: =G18*450+G19*550+G20*500 -> 42873000 | H31: =H18*450+H19*550+H20*500 -> 42423500 | I31: =I18*450+I19*550+I20*500 -> 41973750 | J31: =J18*450+J19*550+J20*500 -> 41548500 | ... AM31: =AM18*450+AM19*550+AM20*500 -> 35819000
A32: 绿电占比 | B32: 电力结构公式 | C32: 0 | D32: 0.016666667 | E32: 0.033333333 | F32: 0.05 | G32: 0.066666667 | H32: 0.083333333 | I32: 0.1 | J32: 0.12 | K32: 0.14 | L32: 0.16 | M32: 0.18 | N32: 0.2 | O32: 0.23 | P32: 0.26 | Q32: 0.29 | R32: 0.32 | S32: 0.35 | T32: 0.367 | U32: 0.384 | V32: 0.401 | W32: 0.418 | X32: 0.435 | Y32: 0.452 | Z32: 0.469 | AA32: 0.486 | AB32: 0.503 | AC32: 0.52 | AD32: 0.54 | AE32: 0.56 | AF32: 0.58 | AG32: 0.6 | AH32: 0.62 | AI32: 0.64 | AJ32: 0.66 | AK32: 0.68 | AL32: 0.7 | AM32: 0.72
A33: 总绿电量(万kWh) | B33: 电力结构公式 | C33: =C31*C32 -> 0 | D33: =D31*D32 -> 737621.84 | E33: =E31*E32 -> 1459041.7 | F33: =F31*F32 -> 2166112.5 | G33: =G31*G32 -> 2858200 | H33: =H31*H32 -> 3535291.7 | I33: =I31*I32 -> 4197375 | J33: =J31*J32 -> 4985820 | ... AM33: =AM31*AM32 -> 25789680
A34: Step 7: 低碳技术
A35: 低碳技术名称 | B35: 逐年技术部署 | C35: 干熄焦技术(已部署,含于基准) | D35: 厚料层烧结技术 | E35: 球团废热循环利用技术 | F35: - | G35: 高炉炉顶煤气干式余压发电技术(TRT) | H35: 高炉冲渣水直接换热回收余热技术 | I35: - | J35: 转炉气体及显热回收技术 | K35: 转炉'负能炼钢'工艺技术 | L35: 钢包加盖技术 | M35: 钢包周转优化技术 | N35: 废钢预热技术 | O35: 电源及电控系统智能化控制技术 | P35: 电炉连续加料技术 | Q35: - | R35: - | S35: - | T35: - | U35: - | V35: 连铸坯热送热装技术 | W35: - | X35: - | Y35: - | Z35: 薄板坯连铸技术 | AA35: - | AB35: - | AC35: - | AD35: - | AE35: - | AF35: - | AG35: - | AH35: - | AI35: - | AJ35: - | AK35: - | AL35: - | AM35: -
A36: 当年降碳潜力(tCO2/t) | B36: 逐年假设(可调) | C36: 0 | D36: 0.0005 | E36: 0.001 | F36: 0.0015 | G36: 0.002 | H36: 0.0025 | I36: 0.003 | J36: 0.0044 | K36: 0.0058 | L36: 0.0072 | M36: 0.0086 | N36: 0.01 | O36: 0.0116 | P36: 0.0132 | Q36: 0.0148 | R36: 0.0164 | S36: 0.018 | T36: 0.0184 | U36: 0.0188 | V36: 0.0192 | W36: 0.0196 | X36: 0.02 | Y36: 0.0204 | Z36: 0.0208 | AA36: 0.0212 | AB36: 0.0216 | AC36: 0.022 | AD36: 0.0213 | AE36: 0.0206 | AF36: 0.0199 | AG36: 0.0192 | AH36: 0.0185 | AI36: 0.0178 | AJ36: 0.0171 | AK36: 0.0164 | AL36: 0.0157 | AM36: 0.015
A37: 累计降碳潜力(tCO2/t) | B37: =上年累计+当年新增 -> #NAME? | C37: =C36 -> 0 | D37: =C37+D36 -> 0.0005 | E37: =D37+E36 -> 0.0015 | F37: =E37+F36 -> 0.003 | G37: =F37+G36 -> 0.005 | H37: =G37+H36 -> 0.0075 | I37: =H37+I36 -> 0.0105 | J37: =I37+J36 -> 0.0149 | K37: =J37+K36 -> 0.0207 | ... AM37: =AL37+AM36 -> 0.504
A38: 原始累计(含基准1.95内) | B38: =模型累计+0.066 -> #NAME? | C38: =C37+0.066 -> 0.066 | D38: =D37+0.066 -> 0.0665 | E38: =E37+0.066 -> 0.0675 | F38: =F37+0.066 -> 0.069 | G38: =G37+0.066 -> 0.071 | H38: =H37+0.066 -> 0.0735 | I38: =I37+0.066 -> 0.0765 | J38: =J37+0.066 -> 0.0809 | ... AM38: =AM37+0.066 -> 0.57
A39: Step 8: 低碳发展测算表(Waterfall)
A40: 8.1 产量变化
A41: 产量变化碳排放曲线(万吨CO2) | B41: =粗钢产量×1.95 -> #NAME? | C41: =C13*1.95 -> 195992.55 | D41: =D13*1.95 -> 187357.95 | E41: =E13*1.95 -> 185250 | F41: =F13*1.95 -> 183300 | G41: =G13*1.95 -> 181350 | H41: =H13*1.95 -> 179400 | I41: =I13*1.95 -> 177450 | J41: =J13*1.95 -> 175500 | ... AM41: =AM13*1.95 -> 142545
...

Sheet 汇总对比与可视化看板
A1: 三情景碳强度对比与关键指标汇总
A2: 年份 | B2: 保守情景吨钢碳强度 | C2: 保守累计降幅 | D2: 适度情景吨钢碳强度 | E2: 适度累计降幅 | F2: 积极情景吨钢碳强度 | G2: 积极累计降幅 | H2: 适度vs保守(百分点) | I2: 积极vs适度(百分点) | J2: 适度情景CO2排放(万吨) | K2: 积极情景CO2排放(万吨)
A3: 2024 | B3: 1.95 | C3: 0 | D3: 1.95 | E3: 0 | F3: 1.95 | G3: 0 | H3: 0 | I3: 0 | J3: 195993 | K3: 195993
A4: 2025 | B4: 1.958 | C4: -0.004 | D4: 1.954 | E4: -0.002 | F4: 1.947 | G4: 0.0015 | H4: 0.2 | I4: 0.35 | J4: 187742 | K4: 187070
A5: 2026 | B5: 1.941 | C5: 0.0046 | D5: 1.923 | E5: 0.0138 | F5: 1.905 | G5: 0.0231 | H5: 0.92 | I5: 0.93 | J5: 180762 | K5: 179070
A6: 2027 | B6: 1.924 | C6: 0.0133 | D6: 1.891 | E6: 0.0303 | F6: 1.853 | G6: 0.0497 | H6: 1.7 | I6: 1.94 | J6: 174918 | K6: 171403
A7: 2028 | B7: 1.907 | C7: 0.0221 | D7: 1.86 | E7: 0.0462 | F7: 1.812 | G7: 0.0708 | H7: 2.41 | I7: 2.46 | J7: 169260 | K7: 164892
A8: 2029 | B8: 1.891 | C8: 0.0303 | D8: 1.829 | E8: 0.0621 | F8: 1.78 | G8: 0.0972 | H8: 3.18 | I8: 2.51 | J8: 160952 | K8: 156640
A9: 2030 | B9: 1.874 | C9: 0.039 | D9: 1.798 | E9: 0.0779 | F9: 1.744 | G9: 0.1206 | H9: 3.89 | I9: 2.77 | J9: 152830 | K9: 148240
A10: 2031 | B10: 1.849 | C10: 0.0518 | D10: 1.76 | E10: 0.0974 | F10: 1.669 | G10: 0.1441 | H10: 4.56 | I10: 4.67 | J10: 148252 | K10: 140582
A11: 2032 | B11: 1.825 | C11: 0.0641 | D11: 1.722 | E11: 0.1169 | F11: 1.594 | G11: 0.1726 | H11: 5.28 | I11: 6.57 | J11: 143878 | K11: 133185
A12: 2033 | B12: 1.8 | C12: 0.0769 | D12: 1.684 | E12: 0.1364 | F12: 1.52 | G12: 0.2005 | H12: 5.95 | I12: 8.41 | J12: 139521 | K12: 125910
A13: 2034 | B13: 1.776 | C13: 0.0892 | D13: 1.646 | E13: 0.1559 | F13: 1.445 | G13: 0.229 | H13: 6.67 | I13: 10.31 | J13: 135221 | K13: 118720
A14: 2035 | B14: 1.751 | C14: 0.102 | D14: 1.607 | E14: 0.1759 | F14: 1.37 | G14: 0.2574 | H14: 7.39 | I14: 12.15 | J14: 134988 | K14: 115080
... A39: 2060 | B39: 0.12 | C39: 0.9385 | D39: 0.05 | E39: 0.9744 | F39: 0.01 | G39: 0.9949 | H39: 3.59 | I39: 2.05 | J39: 2636 | K39: 527

Sheet 金融机构目标设置（组合估算）
A1: 金融机构钢铁行业投融资组合减碳目标对标
A2: 基于适度情景 | 技术路径降碳潜力与适度情景一致
A4: 银行输入参数
A5: 钢铁行业贷款总额(亿元) | C5: 请输入
A6: 加权平均碳强度起点(tCO2/t) | C6: 请输入
A7: 2030年碳强度目标(tCO2/t) | C7: 请输入
A8: 2035年碳强度目标(tCO2/t) | C8: 请输入
A9: 2040年碳强度目标(tCO2/t) | C9: 请输入
A12: 适度情景各减排路径贡献(万吨CO2)
A13: 年份 | B13: 产量变化 | C13: 原料结构 | D13: 短流程提升 | E13: 氢冶金提升 | F13: 绿电 | G13: 低碳技术 | H13: CCUS
A14: 2024 | B14: 0 | C14: 0 | D14: 0 | E14: 0 | F14: 0 | G14: 0 | H14: 0
A16: 2025 | B16: 8634.6 | C16: -2052.3434 | D16: -613.7208 | E16: 37.48829 | F16: 1173.9553 | G16: 5764.86 | H16: 0
A18: 2026 | B18: 13170.57 | C18: -2822.1283 | D18: -546.29088 | E18: 152.15381 | F18: 1692.0092 | G18: 6328.4532 | H18: 0
A20: 2027 | B20: 17596.723 | C20: -3573.1905 | D20: -489.93137 | E20: 284.0094 | F20: 2438.7656 | G20: 6175.2402 | H20: 0
A22: 2028 | B22: 21915.719 | C22: -4304.806 | D22: -444.14576 | E22: 435.63214 | F22: 3515.252 | G22: 8614.5714 | H22: 0
A24: 2029 | B24: 26130.15 | C24: -5016.1203 | D24: -408.45509 | E24: 609.9854 | F24: 5067.1682 | G24: 10409.516 | H24: 0
A26: 2030 | B26: 30242.55 | C26: -5706.1285 | D26: -382.3974 | E26: 810.47683 | F26: 7304.6707 | G26: 10157.5 | H26: 650
A28: 2031 | B28: 31677.822 | C28: -5897.9581 | D28: -336.20857 | E28: 947.41979 | F28: 7931.0278 | G28: 10457.158 | H28: 1160.5
A30: 2032 | B30: 33100.667 | C30: -6084.5914 | D30: -291.83554 | E30: 1096.5572 | F30: 8611.3163 | G30: 15587.5 | H30: 1104.9332
A32: 2033 | B32: 34511.19 | C32: -6265.6606 | D32: -249.25033 | E32: 1258.975 | F32: 9350.2228 | G32: 15618.146 | H32: 1879.3986
A34: 2034 | B34: 35909.499 | C34: -6440.7652 | D34: -208.4253 | E34: 1435.8558 | F34: 10152.849 | G34: 15729.186 | H34: 2197.5465
A36: 2035 | B36: 37295.7 | C36: -6609.4689 | D36: -169.33316 | E36: 1628.4874 | F36: 11024.75 | G36: 18604.154 | H36: 2499.875
... A86: 2060 | B86: 93174.9 | C86: 247.57282 | D86: 22609.264 | E86: 5377.9676 | F86: 13501.674 | G86: 19962.442 | H86: 40802.368

Sheet 金融机构目标设置（企业）
A1: 龙头企业碳减排目标对标与企业级路径验证
A3: 国内龙头钢铁企业碳减排目标
A4: 企业 | B4: 碳达峰年份 | C4: 目标年份 | D4: 目标减排幅度 | E4: 2024-2030折算减排幅度 | F4: 备注
A5: 宝武集团 | B5: 2023 | C5: 2035 | D5: 较2020年吨钢碳排放强度下降30% | E5: 13.3% | F5: 行业龙头
A7: 宝钢股份 | B7: 2023 | C7: 2035 | D7: 较2020年吨钢碳排放强度下降30% | E7: 13.3%
A9: 鞍钢股份 | B9: 2025 | C9: 2035 | D9: 较2025年吨钢碳排放强度下降30% | E9: 19.3%
A11: 首钢股份 | B11: 2025 | C11: 2035 | D11: 较2025年碳排放总量下降30% | E11: 19.3% | F11: 总量指标
A13: 河钢集团 | B13: 2022 | C13: 2030 | D13: 较2022年吨钢碳排放强度下降30% | E13: 23.4%
A15: 建龙集团 | B15: 2025 | C15: 2033 | D15: 较2020年吨钢碳排放强度下降25% | E15: 12.4%
A17: 中信特钢 | B17: 2030 | C17: 2030 | D17: 较2021年吨钢碳排放强度下降5% | E17: 3.4% | F17: 已达峰
A19: 2024-2030年碳减排目标均值 | E19: 14.9%
A21: 标杆企业路径还原(宝山钢铁)
A22: 指标 | B22: 2020 | C22: 2023 | D22: 2024 | E22: 2025(目标) | F22: 2030(目标)
A23: 吨钢碳排放强度(tCO2e/t) | B23: 2.13 | C23: 2.04 | D23: 2.00 | E23: 1.96 | F23: 1.81
A24: 相对指数(2020=1.00) | B24: 1.00 | C24: 0.96 | D24: 0.94 | E24: 0.92 | F24: 0.85
A25: 阶段降幅 | B25: - | C25: -4.0% | D25: -2.0% | E25: -2.2% | F25: -7.1%
A27: 阶段性降碳斜率校验
A28: 计算步骤 | B28: 公式 | C28: 结果
A29: 2025/2024碳强度比 | B29: 0.92/0.94 | C29: 0.979
A30: 2030/2025碳强度比 | B30: 0.85/0.92 | C30: 0.924
A31: 2030/2024碳强度比 | B31: 0.85/0.94 | C31: 0.905
A32: 2024-2030累计降幅 | B32: 1-0.905 | C32: 9.5%
A33: CAGR折算比例 | B33: 9.5%/13.3% | C33: 71.4%
A34: 行业龙头修正后降幅 | B34: 14.9%×71.4% | C34: 10.64%
A36: 行业降碳能力分层测算
A37: 分类 | B37: 占比 | C37: 降碳幅度 | D37: 加权
A38: 头部企业(CR10) | B38: 42% | C38: 10.64% | D38: 4.47%
A39: 其他企业 | B39: 58% | C39: 5.85% | D39: 3.39%
A40: 行业整体 | B40: 100% | C40: - | D40: 7.86%
A42: 信贷组合校正
A43: 客户类型 | B43: 占比 | C43: 降碳贡献 | D43: 加权
A44: 国央企(结构减排) | B44: 70% | C44: 7.86% | D44: 5.50%
A45: 流动资金贷款 | B45: 20% | C45: 0% | D45: 0%
A46: 其他 | B46: 10% | C46: 3% | D46: 0.30%
A47: 组合碳强度降幅 | B47: 100% | C47: - | D47: 5.80%
